Workbook

Sheet Lisez-moi
A1: ARMEMENT01 · Catalogue complet (12 onglets) · contrat v0.3 + jalon ARMEMENT01.2
A2: 82 archétypes · 1640 versions immuables · vrais dés RPG · données historiques conservées
A4: Objet | B4: Ce classeur décrit 82 archétypes d'armes, de focaliseurs et de boucliers; ce ne sont PAS 82 DataAssets UE5 déjà créés.
A5: Onglet Catalogue | B5: Identité par famille : type, dégâts niveau 1, coût PA, portée, poids, attribut, bonus précision et rôle tactique.
A6: Onglet Niveaux 1-20 | B6: 82 archétypes × 20 versions de butin. Jet de dégâts = NdM + K, dés d4/d6/d8/d10/d12/d20; les plages Min/Max sont une conséquence.
A7: Onglet Raretés | B7: Commun gris, Rare vert, Épique bleu, Légendaire violet, Unique doré. Aucun bonus WD de rareté automatique.
A8: Onglet Classes | B8: 6 classes et 18 spécialités canoniques; préférences de gameplay, non restrictions absolues.
A9: Onglet Améliorations | B9: Forge sans gain de niveau, alchimie temporaire, runes permanentes. FOR02/FOR03/FOR07 corrigées selon ARM-001.
A10: Onglet Uniques | B10: Exemples d'objets nommés, avec effet prédéfini et acquisition scénarisée.
A11: Onglet Paramètres | B11: Courbe indicative (k1/k2) pour orienter l'équilibrage; ne régénère pas les dés sans re-authoring explicite.
A12: Onglet Implémentation UE5 | B12: Paramètres de progression à la création de l'objet (niveau fixe), plus paramètres proposés de sous-niveau.
A13: ATTENTION | B13: Valeurs indicatives de game design. À calibrer contre PV/armures monstres, 4 PA/tour, critique, WD et difficulté réelle.
A14: Courbe d'équilibrage | B14: La courbe k1/k2 sert uniquement de cible de comparaison (colonnes Q:R). Les profils de dés M:N:O sont authorés et fixes pour chaque version de butin.
A15: Références | B15: ARMEMENT01_Contrat_Armement_v0_3.md (design) ; ARMEMENT01_2_CONTRAT_TECHNIQUE_MULTIDES.md (contrat technique).
... A26: Contrôles de données | B26: Dans 'Niveaux 1-20', colonnes T:V vérifient faces autorisées, bornes et moyenne de chaque profil sans modifier A:S.

Sheet Catalogue
A1: Catalogue d'armement
A2: Une ligne = un ARCHÉTYPE. E/F sont les CIBLES historiques N1, non les dégâts authorés; la source des dégâts jouables est la table des vrais dés par niveau.
A3: ID | B3: Nom | C3: Famille | D3: Tenue | E3: Min cible N1 | F3: Max cible N1 | G3: Arm phys N1 | H3: Arm mag N1 | I3: PA | J3: Portée cases | K3: Poids kg | L3: Précision | M3: Attribut | N3: Dégâts | O3: Sous-type | P3: Classe principale | Q3: Classes secondaires | R3: Particularité | S3: Tags proposés | T3: Dés N1 réels (voir versions)
A4: ARM001 | B4: Dague | C4: Légères | D4: 1 main | E4: 2 | F4: 4 | G4: 0 | H4: 0 | I4: 2 | J4: 1 | K4: 0.4 | L4: 1 | M4: Dextérité | N4: Physical | O4: Slashing | P4: Voleur | Q4: Rôdeur / Alchimiste | R4: Polyvalente, double arme | S4: Weapon.Light | T4: 1d4
A5: ARM002 | B5: Poignard d'assassin | C5: Légères | D5: 1 main | E5: 2 | F5: 3 | G5: 0 | H5: 0 | I5: 2 | J5: 1 | K5: 0.3 | L5: 2 | M5: Dextérité | N5: Physical | O5: Piercing | P5: Voleur | Q5: Rôdeur / Alchimiste | R5: Critique conditionnel depuis l'ombre | S5: Weapon.Light | T5: 1d4
A6: ARM003 | B6: Stylet | C6: Légères | D6: 1 main | E6: 1 | F6: 4 | G6: 0 | H6: 0 | I6: 2 | J6: 1 | K6: 0.25 | L6: 1 | M6: Dextérité | N6: Physical | O6: Piercing | P6: Voleur | Q6: Rôdeur / Alchimiste | R6: Perforation ciblée | S6: Weapon.Light | T6: 1d4
A7: ARM004 | B7: Kriss | C7: Légères | D7: 1 main | E7: 2 | F7: 4 | G7: 0 | H7: 0 | I7: 2 | J7: 1 | K7: 0.5 | L7: 0 | M7: Dextérité | N7: Physical | O7: Slashing | P7: Voleur | Q7: Rôdeur / Alchimiste | R7: Saigne sur coup critique | S7: Weapon.Light | T7: 1d4
A8: ARM005 | B8: Couteau de chasse | C8: Légères | D8: 1 main | E8: 2 | F8: 4 | G8: 0 | H8: 0 | I8: 2 | J8: 1 | K8: 0.5 | L8: 0 | M8: Dextérité | N8: Physical | O8: Slashing | P8: Voleur | Q8: Rôdeur / Alchimiste | R8: Chasse et utilitaire | S8: Weapon.Light | T8: 1d4
A9: ARM006 | B9: Épée courte | C9: Légères | D9: 1 main | E9: 3 | F9: 5 | G9: 0 | H9: 0 | I9: 2 | J9: 1 | K9: 1 | L9: 0 | M9: Dextérité | N9: Physical | O9: Slashing | P9: Voleur | Q9: Rôdeur / Alchimiste | R9: Bon compromis | S9: Weapon.Light | T9: 1d4 + 1
A10: ARM007 | B10: Rapière | C10: Légères | D10: 1 main | E10: 2 | F10: 5 | G10: 0 | H10: 0 | I10: 2 | J10: 1 | K10: 1 | L10: 1 | M10: Dextérité | N10: Physical | O10: Piercing | P10: Voleur | Q10: Rôdeur / Alchimiste | R10: Parade et précision | S10: Weapon.Light | T10: 1d4 + 1
A11: ARM008 | B11: Sabre léger | C11: Légères | D11: 1 main | E11: 3 | F11: 5 | G11: 0 | H11: 0 | I11: 2 | J11: 1 | K11: 1.1 | L11: 0 | M11: Dextérité | N11: Physical | O11: Slashing | P11: Voleur | Q11: Rôdeur / Alchimiste | R11: Mobilité | S11: Weapon.Light | T11: 1d4 + 1
A12: ARM009 | B12: Cimeterre court | C12: Légères | D12: 1 main | E12: 3 | F12: 5 | G12: 0 | H12: 0 | I12: 2 | J12: 1 | K12: 1.2 | L12: 0 | M12: Dextérité | N12: Physical | O12: Slashing | P12: Voleur | Q12: Rôdeur / Alchimiste | R12: Tranchant | S12: Weapon.Light | T12: 1d4 + 1
A13: ARM010 | B13: Hachette | C13: Légères | D13: 1 main | E13: 3 | F13: 5 | G13: 0 | H13: 0 | I13: 2 | J13: 1 | K13: 1.1 | L13: -1 | M13: Dextérité | N13: Physical | O13: Slashing | P13: Voleur | Q13: Rôdeur / Alchimiste | R13: Peut être lancée selon version | S13: Weapon.Light | T13: 1d4 + 1
A14: ARM011 | B14: Serpe | C14: Légères | D14: 1 main | E14: 2 | F14: 4 | G14: 0 | H14: 0 | I14: 2 | J14: 1 | K14: 0.7 | L14: 0 | M14: Dextérité | N14: Physical | O14: Slashing | P14: Voleur | Q14: Rôdeur / Alchimiste | R14: Affinité poison | S14: Weapon.Light | T14: 1d4
A15: ARM012 | B15: Gourdin léger | C15: Légères | D15: 1 main | E15: 2 | F15: 4 | G15: 0 | H15: 0 | I15: 2 | J15: 1 | K15: 0.8 | L15: 0 | M15: Dextérité | N15: Physical | O15: Bludgeoning | P15: Voleur | Q15: Rôdeur / Alchimiste | R15: Contondant discret | S15: Weapon.Light | T15: 1d4
... A85: ARM082 | B85: Bouclier runique | C85: Boucliers | D85: Secondaire | E85: 0 | F85: 0 | G85: 4 | H85: 4 | I85: 0 | J85: 0 | K85: 3.5 | L85: 0 | M85: Constitution | N85: Physical | O85: Bludgeoning | P85: Guerrier | Q85: Prêtre / Mage | R85: Protection magique | S85: Equipment.Shield | T85: —

Sheet Niveaux 1-20
A1: ARMEMENT01 · Versions fixes niveau 1–20 — DÉS RPG CLASSIQUES
A2: Chaque profil offensif définit ses vrais dés : d4, d6, d8, d10, d12, d20. Plusieurs dés sont additionnés. Les moyennes cibles Q:S servent à l'équilibrage, PAS au tirage.
A3: ID | B3: Arme / bouclier | C3: Niveau OBJET | D3: Famille | E3: Dégâts min | F3: Dégâts max | G3: Arm. physique | H3: Arm. magique | I3: Coût PA | J3: Portée | K3: Poids kg | L3: Dégâts moyens | M3: Nb dés | N3: Faces officielles | O3: Constante | P3: Jet de dégâts (réel) | Q3: Min cible (courbe) | R3: Max cible (courbe) | S3: Écart de moyenne | T3: Profil dés valide | U3: Moyenne dérivée des dés | V3: Moyenne conforme
A4: ARM001 | B4: Dague | C4: 1 | D4: Légères | E4: =IF(M4=0,0,M4+O4) -> 1 | F4: =IF(M4=0,0,M4*N4+O4) -> 4 | G4: =ROUND(Catalogue!G4*SQRT((1+Paramètres!$B$4*(C4-1)+Paramètres!$B$5*(C4-1)^2)),0) -> 0 | H4: =ROUND(Catalogue!H4*SQRT((1+Paramètres!$B$4*(C4-1)+Paramètres!$B$5*(C4-1)^2)),0) -> 0 | I4: 2 | J4: 1 | K4: 0.4 | L4: =IF(M4=0,0,(E4+F4)/2) -> 2.5 | M4: 1 | N4: 4 | O4: 0 | P4: =IF(M4=0,"—",M4&"d"&N4&IF(O4=0,""," + "&O4)) -> 1d4 | Q4: =ROUND(INDEX(Catalogue!E$4:E$85,MATCH(A4,Catalogue!A$4:A$85,0))*(1+Paramètres!$B$4*(C4-1)+Paramètres!$B$5*(C4-1)^2),0) -> 2 | R4: =ROUND(INDEX(Catalogue!F$4:F$85,MATCH(A4,Catalogue!A$4:A$85,0))*(1+Paramètres!$B$4*(C4-1)+Paramètres!$B$5*(C4-1)^2),0) -> 4 | S4: =L4-AVERAGE(Q4:R4) -> -0.5 | T4: =IF(M4=0,IF(AND(N4=0,O4=0,E4=0,F4=0),"OK","ERREUR"),IF(AND(M4>=1,M4<=32,OR(N4=4,N4=6,N4=8,N4=10,N4=12,N4=20),O4>=0,E4=M4+O4,F4=M4*N4+O4),"OK","ERREUR")) -> OK | U4: =IF(M4>0,M4*(N4+1)/2+O4,0) -> 2.5 | V4: =IF(ABS(L4-U4)<0.001,"OK","ERREUR") -> OK
A5: ARM001 | B5: Dague | C5: 2 | D5: Légères | E5: =IF(M5=0,0,M5+O5) -> 2 | F5: =IF(M5=0,0,M5*N5+O5) -> 5 | G5: =ROUND(Catalogue!G4*SQRT((1+Paramètres!$B$4*(C5-1)+Paramètres!$B$5*(C5-1)^2)),0) -> 0 | H5: =ROUND(Catalogue!H4*SQRT((1+Paramètres!$B$4*(C5-1)+Paramètres!$B$5*(C5-1)^2)),0) -> 0 | I5: 2 | J5: 1 | K5: 0.4 | L5: =IF(M5=0,0,(E5+F5)/2) -> 3.5 | M5: 1 | N5: 4 | O5: 1 | P5: =IF(M5=0,"—",M5&"d"&N5&IF(O5=0,""," + "&O5)) -> 1d4 + 1 | Q5: =ROUND(INDEX(Catalogue!E$4:E$85,MATCH(A5,Catalogue!A$4:A$85,0))*(1+Paramètres!$B$4*(C5-1)+Paramètres!$B$5*(C5-1)^2),0) -> 2 | R5: =ROUND(INDEX(Catalogue!F$4:F$85,MATCH(A5,Catalogue!A$4:A$85,0))*(1+Paramètres!$B$4*(C5-1)+Paramètres!$B$5*(C5-1)^2),0) -> 5 | S5: =L5-AVERAGE(Q5:R5) -> 0 | T5: =IF(M5=0,IF(AND(N5=0,O5=0,E5=0,F5=0),"OK","ERREUR"),IF(AND(M5>=1,M5<=32,OR(N5=4,N5=6,N5=8,N5=10,N5=12,N5=20),O5>=0,E5=M5+O5,F5=M5*N5+O5),"OK","ERREUR")) -> OK | U5: =IF(M5>0,M5*(N5+1)/2+O5,0) -> 3.5 | V5: =IF(ABS(L5-U5)<0.001,"OK","ERREUR") -> OK
A6: ARM001 | B6: Dague | C6: 3 | D6: Légères | E6: =IF(M6=0,0,M6+O6) -> 2 | F6: =IF(M6=0,0,M6*N6+O6) -> 5 | G6: =ROUND(Catalogue!G4*SQRT((1+Paramètres!$B$4*(C6-1)+Paramètres!$B$5*(C6-1)^2)),0) -> 0 | H6: =ROUND(Catalogue!H4*SQRT((1+Paramètres!$B$4*(C6-1)+Paramètres!$B$5*(C6-1)^2)),0) -> 0 | I6: 2 | J6: 1 | K6: 0.4 | L6: =IF(M6=0,0,(E6+F6)/2) -> 3.5 | M6: 1 | N6: 4 | O6: 1 | P6: =IF(M6=0,"—",M6&"d"&N6&IF(O6=0,""," + "&O6)) -> 1d4 + 1 | Q6: =ROUND(INDEX(Catalogue!E$4:E$85,MATCH(A6,Catalogue!A$4:A$85,0))*(1+Paramètres!$B$4*(C6-1)+Paramètres!$B$5*(C6-1)^2),0) -> 3 | R6: =ROUND(INDEX(Catalogue!F$4:F$85,MATCH(A6,Catalogue!A$4:A$85,0))*(1+Paramètres!$B$4*(C6-1)+Paramètres!$B$5*(C6-1)^2),0) -> 5 | S6: =L6-AVERAGE(Q6:R6) -> -0.5 | T6: =IF(M6=0,IF(AND(N6=0,O6=0,E6=0,F6=0),"OK","ERREUR"),IF(AND(M6>=1,M6<=32,OR(N6=4,N6=6,N6=8,N6=10,N6=12,N6=20),O6>=0,E6=M6+O6,F6=M6*N6+O6),"OK","ERREUR")) -> OK | U6: =IF(M6>0,M6*(N6+1)/2+O6,0) -> 3.5 | V6: =IF(ABS(L6-U6)<0.001,"OK","ERREUR") -> OK
A7: ARM001 | B7: Dague | C7: 4 | D7: Légères | E7: =IF(M7=0,0,M7+O7) -> 3 | F7: =IF(M7=0,0,M7*N7+O7) -> 6 | G7: =ROUND(Catalogue!G4*SQRT((1+Paramètres!$B$4*(C7-1)+Paramètres!$B$5*(C7-1)^2)),0) -> 0 | H7: =ROUND(Catalogue!H4*SQRT((1+Paramètres!$B$4*(C7-1)+Paramètres!$B$5*(C7-1)^2)),0) -> 0 | I7: 2 | J7: 1 | K7: 0.4 | L7: =IF(M7=0,0,(E7+F7)/2) -> 4.5 | M7: 1 | N7: 4 | O7: 2 | P7: =IF(M7=0,"—",M7&"d"&N7&IF(O7=0,""," + "&O7)) -> 1d4 + 2 | Q7: =ROUND(INDEX(Catalogue!E$4:E$85,MATCH(A7,Catalogue!A$4:A$85,0))*(1+Paramètres!$B$4*(C7-1)+Paramètres!$B$5*(C7-1)^2),0) -> 3 | R7: =ROUND(INDEX(Catalogue!F$4:F$85,MATCH(A7,Catalogue!A$4:A$85,0))*(1+Paramètres!$B$4*(C7-1)+Paramètres!$B$5*(C7-1)^2),0) -> 6 | S7: =L7-AVERAGE(Q7:R7) -> 0 | T7: =IF(M7=0,IF(AND(N7=0,O7=0,E7=0,F7=0),"OK","ERREUR"),IF(AND(M7>=1,M7<=32,OR(N7=4,N7=6,N7=8,N7=10,N7=12,N7=20),O7>=0,E7=M7+O7,F7=M7*N7+O7),"OK","ERREUR")) -> OK | U7: =IF(M7>0,M7*(N7+1)/2+O7,0) -> 4.5 | V7: =IF(ABS(L7-U7)<0.001,"OK","ERREUR") -> OK
A8: ARM001 | B8: Dague | C8: 5 | D8: Légères | E8: =IF(M8=0,0,M8+O8) -> 3 | F8: =IF(M8=0,0,M8*N8+O8) -> 6 | G8: =ROUND(Catalogue!G4*SQRT((1+Paramètres!$B$4*(C8-1)+Paramètres!$B$5*(C8-1)^2)),0) -> 0 | H8: =ROUND(Catalogue!H4*SQRT((1+Paramètres!$B$4*(C8-1)+Paramètres!$B$5*(C8-1)^2)),0) -> 0 | I8: 2 | J8: 1 | K8: 0.4 | L8: =IF(M8=0,0,(E8+F8)/2) -> 4.5 | M8: 1 | N8: 4 | O8: 2 | P8: =IF(M8=0,"—",M8&"d"&N8&IF(O8=0,""," + "&O8)) -> 1d4 + 2 | Q8: =ROUND(INDEX(Catalogue!E$4:E$85,MATCH(A8,Catalogue!A$4:A$85,0))*(1+Paramètres!$B$4*(C8-1)+Paramètres!$B$5*(C8-1)^2),0) -> 3 | R8: =ROUND(INDEX(Catalogue!F$4:F$85,MATCH(A8,Catalogue!A$4:A$85,0))*(1+Paramètres!$B$4*(C8-1)+Paramètres!$B$5*(C8-1)^2),0) -> 7 | S8: =L8-AVERAGE(Q8:R8) -> -0.5 | T8: =IF(M8=0,IF(AND(N8=0,O8=0,E8=0,F8=0),"OK","ERREUR"),IF(AND(M8>=1,M8<=32,OR(N8=4,N8=6,N8=8,N8=10,N8=12,N8=20),O8>=0,E8=M8+O8,F8=M8*N8+O8),"OK","ERREUR")) -> OK | U8: =IF(M8>0,M8*(N8+1)/2+O8,0) -> 4.5 | V8: =IF(ABS(L8-U8)<0.001,"OK","ERREUR") -> OK
A9: ARM001 | B9: Dague | C9: 6 | D9: Légères | E9: =IF(M9=0,0,M9+O9) -> 4 | F9: =IF(M9=0,0,M9*N9+O9) -> 7 | G9: =ROUND(Catalogue!G4*SQRT((1+Paramètres!$B$4*(C9-1)+Paramètres!$B$5*(C9-1)^2)),0) -> 0 | H9: =ROUND(Catalogue!H4*SQRT((1+Paramètres!$B$4*(C9-1)+Paramètres!$B$5*(C9-1)^2)),0) -> 0 | I9: 2 | J9: 1 | K9: 0.4 | L9: =IF(M9=0,0,(E9+F9)/2) -> 5.5 | M9: 1 | N9: 4 | O9: 3 | P9: =IF(M9=0,"—",M9&"d"&N9&IF(O9=0,""," + "&O9)) -> 1d4 + 3 | Q9: =ROUND(INDEX(Catalogue!E$4:E$85,MATCH(A9,Catalogue!A$4:A$85,0))*(1+Paramètres!$B$4*(C9-1)+Paramètres!$B$5*(C9-1)^2),0) -> 4 | R9: =ROUND(INDEX(Catalogue!F$4:F$85,MATCH(A9,Catalogue!A$4:A$85,0))*(1+Paramètres!$B$4*(C9-1)+Paramètres!$B$5*(C9-1)^2),0) -> 8 | S9: =L9-AVERAGE(Q9:R9) -> -0.5 | T9: =IF(M9=0,IF(AND(N9=0,O9=0,E9=0,F9=0),"OK","ERREUR"),IF(AND(M9>=1,M9<=32,OR(N9=4,N9=6,N9=8,N9=10,N9=12,N9=20),O9>=0,E9=M9+O9,F9=M9*N9+O9),"OK","ERREUR")) -> OK | U9: =IF(M9>0,M9*(N9+1)/2+O9,0) -> 5.5 | V9: =IF(ABS(L9-U9)<0.001,"OK","ERREUR") -> OK
A10: ARM001 | B10: Dague | C10: 7 | D10: Légères | E10: =IF(M10=0,0,M10+O10) -> 4 | F10: =IF(M10=0,0,M10*N10+O10) -> 9 | G10: =ROUND(Catalogue!G4*SQRT((1+Paramètres!$B$4*(C10-1)+Paramètres!$B$5*(C10-1)^2)),0) -> 0 | H10: =ROUND(Catalogue!H4*SQRT((1+Paramètres!$B$4*(C10-1)+Paramètres!$B$5*(C10-1)^2)),0) -> 0 | I10: 2 | J10: 1 | K10: 0.4 | L10: =IF(M10=0,0,(E10+F10)/2) -> 6.5 | M10: 1 | N10: 6 | O10: 3 | P10: =IF(M10=0,"—",M10&"d"&N10&IF(O10=0,""," + "&O10)) -> 1d6 + 3 | Q10: =ROUND(INDEX(Catalogue!E$4:E$85,MATCH(A10,Catalogue!A$4:A$85,0))*(1+Paramètres!$B$4*(C10-1)+Paramètres!$B$5*(C10-1)^2),0) -> 4 | R10: =ROUND(INDEX(Catalogue!F$4:F$85,MATCH(A10,Catalogue!A$4:A$85,0))*(1+Paramètres!$B$4*(C10-1)+Paramètres!$B$5*(C10-1)^2),0) -> 9 | S10: =L10-AVERAGE(Q10:R10) -> 0 | T10: =IF(M10=0,IF(AND(N10=0,O10=0,E10=0,F10=0),"OK","ERREUR"),IF(AND(M10>=1,M10<=32,OR(N10=4,N10=6,N10=8,N10=10,N10=12,N10=20),O10>=0,E10=M10+O10,F10=M10*N10+O10),"OK","ERREUR")) -> OK | U10: =IF(M10>0,M10*(N10+1)/2+O10,0) -> 6.5 | V10: =IF(ABS(L10-U10)<0.001,"OK","ERREUR") -> OK
A11: ARM001 | B11: Dague | C11: 8 | D11: Légères | E11: =IF(M11=0,0,M11+O11) -> 5 | F11: =IF(M11=0,0,M11*N11+O11) -> 10 | G11: =ROUND(Catalogue!G4*SQRT((1+Paramètres!$B$4*(C11-1)+Paramètres!$B$5*(C11-1)^2)),0) -> 0 | H11: =ROUND(Catalogue!H4*SQRT((1+Paramètres!$B$4*(C11-1)+Paramètres!$B$5*(C11-1)^2)),0) -> 0 | I11: 2 | J11: 1 | K11: 0.4 | L11: =IF(M11=0,0,(E11+F11)/2) -> 7.5 | M11: 1 | N11: 6 | O11: 4 | P11: =IF(M11=0,"—",M11&"d"&N11&IF(O11=0,""," + "&O11)) -> 1d6 + 4 | Q11: =ROUND(INDEX(Catalogue!E$4:E$85,MATCH(A11,Catalogue!A$4:A$85,0))*(1+Paramètres!$B$4*(C11-1)+Paramètres!$B$5*(C11-1)^2),0) -> 5 | R11: =ROUND(INDEX(Catalogue!F$4:F$85,MATCH(A11,Catalogue!A$4:A$85,0))*(1+Paramètres!$B$4*(C11-1)+Paramètres!$B$5*(C11-1)^2),0) -> 10 | S11: =L11-AVERAGE(Q11:R11) -> 0 | T11: =IF(M11=0,IF(AND(N11=0,O11=0,E11=0,F11=0),"OK","ERREUR"),IF(AND(M11>=1,M11<=32,OR(N11=4,N11=6,N11=8,N11=10,N11=12,N11=20),O11>=0,E11=M11+O11,F11=M11*N11+O11),"OK","ERREUR")) -> OK | U11: =IF(M11>0,M11*(N11+1)/2+O11,0) -> 7.5 | V11: =IF(ABS(L11-U11)<0.001,"OK","ERREUR") -> OK
A12: ARM001 | B12: Dague | C12: 9 | D12: Légères | E12: =IF(M12=0,0,M12+O12) -> 6 | F12: =IF(M12=0,0,M12*N12+O12) -> 12 | G12: =ROUND(Catalogue!G4*SQRT((1+Paramètres!$B$4*(C12-1)+Paramètres!$B$5*(C12-1)^2)),0) -> 0 | H12: =ROUND(Catalogue!H4*SQRT((1+Paramètres!$B$4*(C12-1)+Paramètres!$B$5*(C12-1)^2)),0) -> 0 | I12: 2 | J12: 1 | K12: 0.4 | L12: =IF(M12=0,0,(E12+F12)/2) -> 9 | M12: 2 | N12: 4 | O12: 4 | P12: =IF(M12=0,"—",M12&"d"&N12&IF(O12=0,""," + "&O12)) -> 2d4 + 4 | Q12: =ROUND(INDEX(Catalogue!E$4:E$85,MATCH(A12,Catalogue!A$4:A$85,0))*(1+Paramètres!$B$4*(C12-1)+Paramètres!$B$5*(C12-1)^2),0) -> 6 | R12: =ROUND(INDEX(Catalogue!F$4:F$85,MATCH(A12,Catalogue!A$4:A$85,0))*(1+Paramètres!$B$4*(C12-1)+Paramètres!$B$5*(C12-1)^2),0) -> 12 | S12: =L12-AVERAGE(Q12:R12) -> 0 | T12: =IF(M12=0,IF(AND(N12=0,O12=0,E12=0,F12=0),"OK","ERREUR"),IF(AND(M12>=1,M12<=32,OR(N12=4,N12=6,N12=8,N12=10,N12=12,N12=20),O12>=0,E12=M12+O12,F12=M12*N12+O12),"OK","ERREUR")) -> OK | U12: =IF(M12>0,M12*(N12+1)/2+O12,0) -> 9 | V12: =IF(ABS(L12-U12)<0.001,"OK","ERREUR") -> OK
A13: ARM001 | B13: Dague | C13: 10 | D13: Légères | E13: =IF(M13=0,0,M13+O13) -> 7 | F13: =IF(M13=0,0,M13*N13+O13) -> 13 | G13: =ROUND(Catalogue!G4*SQRT((1+Paramètres!$B$4*(C13-1)+Paramètres!$B$5*(C13-1)^2)),0) -> 0 | H13: =ROUND(Catalogue!H4*SQRT((1+Paramètres!$B$4*(C13-1)+Paramètres!$B$5*(C13-1)^2)),0) -> 0 | I13: 2 | J13: 1 | K13: 0.4 | L13: =IF(M13=0,0,(E13+F13)/2) -> 10 | M13: 2 | N13: 4 | O13: 5 | P13: =IF(M13=0,"—",M13&"d"&N13&IF(O13=0,""," + "&O13)) -> 2d4 + 5 | Q13: =ROUND(INDEX(Catalogue!E$4:E$85,MATCH(A13,Catalogue!A$4:A$85,0))*(1+Paramètres!$B$4*(C13-1)+Paramètres!$B$5*(C13-1)^2),0) -> 7 | R13: =ROUND(INDEX(Catalogue!F$4:F$85,MATCH(A13,Catalogue!A$4:A$85,0))*(1+Paramètres!$B$4*(C13-1)+Paramètres!$B$5*(C13-1)^2),0) -> 13 | S13: =L13-AVERAGE(Q13:R13) -> 0 | T13: =IF(M13=0,IF(AND(N13=0,O13=0,E13=0,F13=0),"OK","ERREUR"),IF(AND(M13>=1,M13<=32,OR(N13=4,N13=6,N13=8,N13=10,N13=12,N13=20),O13>=0,E13=M13+O13,F13=M13*N13+O13),"OK","ERREUR")) -> OK | U13: =IF(M13>0,M13*(N13+1)/2+O13,0) -> 10 | V13: =IF(ABS(L13-U13)<0.001,"OK","ERREUR") -> OK
A14: ARM001 | B14: Dague | C14: 11 | D14: Légères | E14: =IF(M14=0,0,M14+O14) -> 6 | F14: =IF(M14=0,0,M14*N14+O14) -> 15 | G14: =ROUND(Catalogue!G4*SQRT((1+Paramètres!$B$4*(C14-1)+Paramètres!$B$5*(C14-1)^2)),0) -> 0 | H14: =ROUND(Catalogue!H4*SQRT((1+Paramètres!$B$4*(C14-1)+Paramètres!$B$5*(C14-1)^2)),0) -> 0 | I14: 2 | J14: 1 | K14: 0.4 | L14: =IF(M14=0,0,(E14+F14)/2) -> 10.5 | M14: 3 | N14: 4 | O14: 3 | P14: =IF(M14=0,"—",M14&"d"&N14&IF(O14=0,""," + "&O14)) -> 3d4 + 3 | Q14: =ROUND(INDEX(Catalogue!E$4:E$85,MATCH(A14,Catalogue!A$4:A$85,0))*(1+Paramètres!$B$4*(C14-1)+Paramètres!$B$5*(C14-1)^2),0) -> 7 | R14: =ROUND(INDEX(Catalogue!F$4:F$85,MATCH(A14,Catalogue!A$4:A$85,0))*(1+Paramètres!$B$4*(C14-1)+Paramètres!$B$5*(C14-1)^2),0) -> 15 | S14: =L14-AVERAGE(Q14:R14) -> -0.5 | T14: =IF(M14=0,IF(AND(N14=0,O14=0,E14=0,F14=0),"OK","ERREUR"),IF(AND(M14>=1,M14<=32,OR(N14=4,N14=6,N14=8,N14=10,N14=12,N14=20),O14>=0,E14=M14+O14,F14=M14*N14+O14),"OK","ERREUR")) -> OK | U14: =IF(M14>0,M14*(N14+1)/2+O14,0) -> 10.5 | V14: =IF(ABS(L14-U14)<0.001,"OK","ERREUR") -> OK
A15: ARM001 | B15: Dague | C15: 12 | D15: Légères | E15: =IF(M15=0,0,M15+O15) -> 8 | F15: =IF(M15=0,0,M15*N15+O15) -> 17 | G15: =ROUND(Catalogue!G4*SQRT((1+Paramètres!$B$4*(C15-1)+Paramètres!$B$5*(C15-1)^2)),0) -> 0 | H15: =ROUND(Catalogue!H4*SQRT((1+Paramètres!$B$4*(C15-1)+Paramètres!$B$5*(C15-1)^2)),0) -> 0 | I15: 2 | J15: 1 | K15: 0.4 | L15: =IF(M15=0,0,(E15+F15)/2) -> 12.5 | M15: 3 | N15: 4 | O15: 5 | P15: =IF(M15=0,"—",M15&"d"&N15&IF(O15=0,""," + "&O15)) -> 3d4 + 5 | Q15: =ROUND(INDEX(Catalogue!E$4:E$85,MATCH(A15,Catalogue!A$4:A$85,0))*(1+Paramètres!$B$4*(C15-1)+Paramètres!$B$5*(C15-1)^2),0) -> 8 | R15: =ROUND(INDEX(Catalogue!F$4:F$85,MATCH(A15,Catalogue!A$4:A$85,0))*(1+Paramètres!$B$4*(C15-1)+Paramètres!$B$5*(C15-1)^2),0) -> 17 | S15: =L15-AVERAGE(Q15:R15) -> 0 | T15: =IF(M15=0,IF(AND(N15=0,O15=0,E15=0,F15=0),"OK","ERREUR"),IF(AND(M15>=1,M15<=32,OR(N15=4,N15=6,N15=8,N15=10,N15=12,N15=20),O15>=0,E15=M15+O15,F15=M15*N15+O15),"OK","ERREUR")) -> OK | U15: =IF(M15>0,M15*(N15+1)/2+O15,0) -> 12.5 | V15: =IF(ABS(L15-U15)<0.001,"OK","ERREUR") -> OK
A16: ARM001 | B16: Dague | C16: 13 | D16: Légères | E16: =IF(M16=0,0,M16+O16) -> 9 | F16: =IF(M16=0,0,M16*N16+O16) -> 18 | G16: =ROUND(Catalogue!G4*SQRT((1+Paramètres!$B$4*(C16-1)+Paramètres!$B$5*(C16-1)^2)),0) -> 0 | H16: =ROUND(Catalogue!H4*SQRT((1+Paramètres!$B$4*(C16-1)+Paramètres!$B$5*(C16-1)^2)),0) -> 0 | I16: 2 | J16: 1 | K16: 0.4 | L16: =IF(M16=0,0,(E16+F16)/2) -> 13.5 | M16: 3 | N16: 4 | O16: 6 | P16: =IF(M16=0,"—",M16&"d"&N16&IF(O16=0,""," + "&O16)) -> 3d4 + 6 | Q16: =ROUND(INDEX(Catalogue!E$4:E$85,MATCH(A16,Catalogue!A$4:A$85,0))*(1+Paramètres!$B$4*(C16-1)+Paramètres!$B$5*(C16-1)^2),0) -> 9 | R16: =ROUND(INDEX(Catalogue!F$4:F$85,MATCH(A16,Catalogue!A$4:A$85,0))*(1+Paramètres!$B$4*(C16-1)+Paramètres!$B$5*(C16-1)^2),0) -> 18 | S16: =L16-AVERAGE(Q16:R16) -> 0 | T16: =IF(M16=0,IF(AND(N16=0,O16=0,E16=0,F16=0),"OK","ERREUR"),IF(AND(M16>=1,M16<=32,OR(N16=4,N16=6,N16=8,N16=10,N16=12,N16=20),O16>=0,E16=M16+O16,F16=M16*N16+O16),"OK","ERREUR")) -> OK | U16: =IF(M16>0,M16*(N16+1)/2+O16,0) -> 13.5 | V16: =IF(ABS(L16-U16)<0.001,"OK","ERREUR") -> OK
A17: ARM001 | B17: Dague | C17: 14 | D17: Légères | E17: =IF(M17=0,0,M17+O17) -> 10 | F17: =IF(M17=0,0,M17*N17+O17) -> 20 | G17: =ROUND(Catalogue!G4*SQRT((1+Paramètres!$B$4*(C17-1)+Paramètres!$B$5*(C17-1)^2)),0) -> 0 | H17: =ROUND(Catalogue!H4*SQRT((1+Paramètres!$B$4*(C17-1)+Paramètres!$B$5*(C17-1)^2)),0) -> 0 | I17: 2 | J17: 1 | K17: 0.4 | L17: =IF(M17=0,0,(E17+F17)/2) -> 15 | M17: 2 | N17: 6 | O17: 8 | P17: =IF(M17=0,"—",M17&"d"&N17&IF(O17=0,""," + "&O17)) -> 2d6 + 8 | Q17: =ROUND(INDEX(Catalogue!E$4:E$85,MATCH(A17,Catalogue!A$4:A$85,0))*(1+Paramètres!$B$4*(C17-1)+Paramètres!$B$5*(C17-1)^2),0) -> 10 | R17: =ROUND(INDEX(Catalogue!F$4:F$85,MATCH(A17,Catalogue!A$4:A$85,0))*(1+Paramètres!$B$4*(C17-1)+Paramètres!$B$5*(C17-1)^2),0) -> 21 | S17: =L17-AVERAGE(Q17:R17) -> -0.5 | T17: =IF(M17=0,IF(AND(N17=0,O17=0,E17=0,F17=0),"OK","ERREUR"),IF(AND(M17>=1,M17<=32,OR(N17=4,N17=6,N17=8,N17=10,N17=12,N17=20),O17>=0,E17=M17+O17,F17=M17*N17+O17),"OK","ERREUR")) -> OK | U17: =IF(M17>0,M17*(N17+1)/2+O17,0) -> 15 | V17: =IF(ABS(L17-U17)<0.001,"OK","ERREUR") -> OK
A18: ARM001 | B18: Dague | C18: 15 | D18: Légères | E18: =IF(M18=0,0,M18+O18) -> 11 | F18: =IF(M18=0,0,M18*N18+O18) -> 23 | G18: =ROUND(Catalogue!G4*SQRT((1+Paramètres!$B$4*(C18-1)+Paramètres!$B$5*(C18-1)^2)),0) -> 0 | H18: =ROUND(Catalogue!H4*SQRT((1+Paramètres!$B$4*(C18-1)+Paramètres!$B$5*(C18-1)^2)),0) -> 0 | I18: 2 | J18: 1 | K18: 0.4 | L18: =IF(M18=0,0,(E18+F18)/2) -> 17 | M18: 4 | N18: 4 | O18: 7 | P18: =IF(M18=0,"—",M18&"d"&N18&IF(O18=0,""," + "&O18)) -> 4d4 + 7 | Q18: =ROUND(INDEX(Catalogue!E$4:E$85,MATCH(A18,Catalogue!A$4:A$85,0))*(1+Paramètres!$B$4*(C18-1)+Paramètres!$B$5*(C18-1)^2),0) -> 11 | R18: =ROUND(INDEX(Catalogue!F$4:F$85,MATCH(A18,Catalogue!A$4:A$85,0))*(1+Paramètres!$B$4*(C18-1)+Paramètres!$B$5*(C18-1)^2),0) -> 23 | S18: =L18-AVERAGE(Q18:R18) -> 0 | T18: =IF(M18=0,IF(AND(N18=0,O18=0,E18=0,F18=0),"OK","ERREUR"),IF(AND(M18>=1,M18<=32,OR(N18=4,N18=6,N18=8,N18=10,N18=12,N18=20),O18>=0,E18=M18+O18,F18=M18*N18+O18),"OK","ERREUR")) -> OK | U18: =IF(M18>0,M18*(N18+1)/2+O18,0) -> 17 | V18: =IF(ABS(L18-U18)<0.001,"OK","ERREUR") -> OK
A19: ARM001 | B19: Dague | C19: 16 | D19: Légères | E19: =IF(M19=0,0,M19+O19) -> 13 | F19: =IF(M19=0,0,M19*N19+O19) -> 25 | G19: =ROUND(Catalogue!G4*SQRT((1+Paramètres!$B$4*(C19-1)+Paramètres!$B$5*(C19-1)^2)),0) -> 0 | H19: =ROUND(Catalogue!H4*SQRT((1+Paramètres!$B$4*(C19-1)+Paramètres!$B$5*(C19-1)^2)),0) -> 0 | I19: 2 | J19: 1 | K19: 0.4 | L19: =IF(M19=0,0,(E19+F19)/2) -> 19 | M19: 4 | N19: 4 | O19: 9 | P19: =IF(M19=0,"—",M19&"d"&N19&IF(O19=0,""," + "&O19)) -> 4d4 + 9 | Q19: =ROUND(INDEX(Catalogue!E$4:E$85,MATCH(A19,Catalogue!A$4:A$85,0))*(1+Paramètres!$B$4*(C19-1)+Paramètres!$B$5*(C19-1)^2),0) -> 13 | R19: =ROUND(INDEX(Catalogue!F$4:F$85,MATCH(A19,Catalogue!A$4:A$85,0))*(1+Paramètres!$B$4*(C19-1)+Paramètres!$B$5*(C19-1)^2),0) -> 25 | S19: =L19-AVERAGE(Q19:R19) -> 0 | T19: =IF(M19=0,IF(AND(N19=0,O19=0,E19=0,F19=0),"OK","ERREUR"),IF(AND(M19>=1,M19<=32,OR(N19=4,N19=6,N19=8,N19=10,N19=12,N19=20),O19>=0,E19=M19+O19,F19=M19*N19+O19),"OK","ERREUR")) -> OK | U19: =IF(M19>0,M19*(N19+1)/2+O19,0) -> 19 | V19: =IF(ABS(L19-U19)<0.001,"OK","ERREUR") -> OK
A20: ARM001 | B20: Dague | C20: 17 | D20: Légères | E20: =IF(M20=0,0,M20+O20) -> 13 | F20: =IF(M20=0,0,M20*N20+O20) -> 27 | G20: =ROUND(Catalogue!G4*SQRT((1+Paramètres!$B$4*(C20-1)+Paramètres!$B$5*(C20-1)^2)),0) -> 0 | H20: =ROUND(Catalogue!H4*SQRT((1+Paramètres!$B$4*(C20-1)+Paramètres!$B$5*(C20-1)^2)),0) -> 0 | I20: 2 | J20: 1 | K20: 0.4 | L20: =IF(M20=0,0,(E20+F20)/2) -> 20 | M20: 2 | N20: 8 | O20: 11 | P20: =IF(M20=0,"—",M20&"d"&N20&IF(O20=0,""," + "&O20)) -> 2d8 + 11 | Q20: =ROUND(INDEX(Catalogue!E$4:E$85,MATCH(A20,Catalogue!A$4:A$85,0))*(1+Paramètres!$B$4*(C20-1)+Paramètres!$B$5*(C20-1)^2),0) -> 14 | R20: =ROUND(INDEX(Catalogue!F$4:F$85,MATCH(A20,Catalogue!A$4:A$85,0))*(1+Paramètres!$B$4*(C20-1)+Paramètres!$B$5*(C20-1)^2),0) -> 27 | S20: =L20-AVERAGE(Q20:R20) -> -0.5 | T20: =IF(M20=0,IF(AND(N20=0,O20=0,E20=0,F20=0),"OK","ERREUR"),IF(AND(M20>=1,M20<=32,OR(N20=4,N20=6,N20=8,N20=10,N20=12,N20=20),O20>=0,E20=M20+O20,F20=M20*N20+O20),"OK","ERREUR")) -> OK | U20: =IF(M20>0,M20*(N20+1)/2+O20,0) -> 20 | V20: =IF(ABS(L20-U20)<0.001,"OK","ERREUR") -> OK
A21: ARM001 | B21: Dague | C21: 18 | D21: Légères | E21: =IF(M21=0,0,M21+O21) -> 15 | F21: =IF(M21=0,0,M21*N21+O21) -> 30 | G21: =ROUND(Catalogue!G4*SQRT((1+Paramètres!$B$4*(C21-1)+Paramètres!$B$5*(C21-1)^2)),0) -> 0 | H21: =ROUND(Catalogue!H4*SQRT((1+Paramètres!$B$4*(C21-1)+Paramètres!$B$5*(C21-1)^2)),0) -> 0 | I21: 2 | J21: 1 | K21: 0.4 | L21: =IF(M21=0,0,(E21+F21)/2) -> 22.5 | M21: 3 | N21: 6 | O21: 12 | P21: =IF(M21=0,"—",M21&"d"&N21&IF(O21=0,""," + "&O21)) -> 3d6 + 12 | Q21: =ROUND(INDEX(Catalogue!E$4:E$85,MATCH(A21,Catalogue!A$4:A$85,0))*(1+Paramètres!$B$4*(C21-1)+Paramètres!$B$5*(C21-1)^2),0) -> 15 | R21: =ROUND(INDEX(Catalogue!F$4:F$85,MATCH(A21,Catalogue!A$4:A$85,0))*(1+Paramètres!$B$4*(C21-1)+Paramètres!$B$5*(C21-1)^2),0) -> 30 | S21: =L21-AVERAGE(Q21:R21) -> 0 | T21: =IF(M21=0,IF(AND(N21=0,O21=0,E21=0,F21=0),"OK","ERREUR"),IF(AND(M21>=1,M21<=32,OR(N21=4,N21=6,N21=8,N21=10,N21=12,N21=20),O21>=0,E21=M21+O21,F21=M21*N21+O21),"OK","ERREUR")) -> OK | U21: =IF(M21>0,M21*(N21+1)/2+O21,0) -> 22.5 | V21: =IF(ABS(L21-U21)<0.001,"OK","ERREUR") -> OK
A22: ARM001 | B22: Dague | C22: 19 | D22: Légères | E22: =IF(M22=0,0,M22+O22) -> 15 | F22: =IF(M22=0,0,M22*N22+O22) -> 33 | G22: =ROUND(Catalogue!G4*SQRT((1+Paramètres!$B$4*(C22-1)+Paramètres!$B$5*(C22-1)^2)),0) -> 0 | H22: =ROUND(Catalogue!H4*SQRT((1+Paramètres!$B$4*(C22-1)+Paramètres!$B$5*(C22-1)^2)),0) -> 0 | I22: 2 | J22: 1 | K22: 0.4 | L22: =IF(M22=0,0,(E22+F22)/2) -> 24 | M22: 2 | N22: 10 | O22: 13 | P22: =IF(M22=0,"—",M22&"d"&N22&IF(O22=0,""," + "&O22)) -> 2d10 + 13 | Q22: =ROUND(INDEX(Catalogue!E$4:E$85,MATCH(A22,Catalogue!A$4:A$85,0))*(1+Paramètres!$B$4*(C22-1)+Paramètres!$B$5*(C22-1)^2),0) -> 16 | R22: =ROUND(INDEX(Catalogue!F$4:F$85,MATCH(A22,Catalogue!A$4:A$85,0))*(1+Paramètres!$B$4*(C22-1)+Paramètres!$B$5*(C22-1)^2),0) -> 33 | S22: =L22-AVERAGE(Q22:R22) -> -0.5 | T22: =IF(M22=0,IF(AND(N22=0,O22=0,E22=0,F22=0),"OK","ERREUR"),IF(AND(M22>=1,M22<=32,OR(N22=4,N22=6,N22=8,N22=10,N22=12,N22=20),O22>=0,E22=M22+O22,F22=M22*N22+O22),"OK","ERREUR")) -> OK | U22: =IF(M22>0,M22*(N22+1)/2+O22,0) -> 24 | V22: =IF(ABS(L22-U22)<0.001,"OK","ERREUR") -> OK
A23: ARM001 | B23: Dague | C23: 20 | D23: Légères | E23: =IF(M23=0,0,M23+O23) -> 18 | F23: =IF(M23=0,0,M23*N23+O23) -> 36 | G23: =ROUND(Catalogue!G4*SQRT((1+Paramètres!$B$4*(C23-1)+Paramètres!$B$5*(C23-1)^2)),0) -> 0 | H23: =ROUND(Catalogue!H4*SQRT((1+Paramètres!$B$4*(C23-1)+Paramètres!$B$5*(C23-1)^2)),0) -> 0 | I23: 2 | J23: 1 | K23: 0.4 | L23: =IF(M23=0,0,(E23+F23)/2) -> 27 | M23: 2 | N23: 10 | O23: 16 | P23: =IF(M23=0,"—",M23&"d"&N23&IF(O23=0,""," + "&O23)) -> 2d10 + 16 | Q23: =ROUND(INDEX(Catalogue!E$4:E$85,MATCH(A23,Catalogue!A$4:A$85,0))*(1+Paramètres!$B$4*(C23-1)+Paramètres!$B$5*(C23-1)^2),0) -> 18 | R23: =ROUND(INDEX(Catalogue!F$4:F$85,MATCH(A23,Catalogue!A$4:A$85,0))*(1+Paramètres!$B$4*(C23-1)+Paramètres!$B$5*(C23-1)^2),0) -> 35 | S23: =L23-AVERAGE(Q23:R23) -> 0.5 | T23: =IF(M23=0,IF(AND(N23=0,O23=0,E23=0,F23=0),"OK","ERREUR"),IF(AND(M23>=1,M23<=32,OR(N23=4,N23=6,N23=8,N23=10,N23=12,N23=20),O23>=0,E23=M23+O23,F23=M23*N23+O23),"OK","ERREUR")) -> OK | U23: =IF(M23>0,M23*(N23+1)/2+O23,0) -> 27 | V23: =IF(ABS(L23-U23)<0.001,"OK","ERREUR") -> OK
A24: ARM002 | B24: Poignard d'assassin | C24: 1 | D24: Légères | E24: =IF(M24=0,0,M24+O24) -> 1 | F24: =IF(M24=0,0,M24*N24+O24) -> 4 | G24: =ROUND(Catalogue!G5*SQRT((1+Paramètres!$B$4*(C24-1)+Paramètres!$B$5*(C24-1)^2)),0) -> 0 | H24: =ROUND(Catalogue!H5*SQRT((1+Paramètres!$B$4*(C24-1)+Paramètres!$B$5*(C24-1)^2)),0) -> 0 | I24: 2 | J24: 1 | K24: 0.3 | L24: =IF(M24=0,0,(E24+F24)/2) -> 2.5 | M24: 1 | N24: 4 | O24: 0 | P24: =IF(M24=0,"—",M24&"d"&N24&IF(O24=0,""," + "&O24)) -> 1d4 | Q24: =ROUND(INDEX(Catalogue!E$4:E$85,MATCH(A24,Catalogue!A$4:A$85,0))*(1+Paramètres!$B$4*(C24-1)+Paramètres!$B$5*(C24-1)^2),0) -> 2 | R24: =ROUND(INDEX(Catalogue!F$4:F$85,MATCH(A24,Catalogue!A$4:A$85,0))*(1+Paramètres!$B$4*(C24-1)+Paramètres!$B$5*(C24-1)^2),0) -> 3 | S24: =L24-AVERAGE(Q24:R24) -> 0 | T24: =IF(M24=0,IF(AND(N24=0,O24=0,E24=0,F24=0),"OK","ERREUR"),IF(AND(M24>=1,M24<=32,OR(N24=4,N24=6,N24=8,N24=10,N24=12,N24=20),O24>=0,E24=M24+O24,F24=M24*N24+O24),"OK","ERREUR")) -> OK | U24: =IF(M24>0,M24*(N24+1)/2+O24,0) -> 2.5 | V24: =IF(ABS(L24-U24)<0.001,"OK","ERREUR") -> OK
A25: ARM002 | B25: Poignard d'assassin | C25: 2 | D25: Légères | E25: =IF(M25=0,0,M25+O25) -> 1 | F25: =IF(M25=0,0,M25*N25+O25) -> 4 | G25: =ROUND(Catalogue!G5*SQRT((1+Paramètres!$B$4*(C25-1)+Paramètres!$B$5*(C25-1)^2)),0) -> 0 | H25: =ROUND(Catalogue!H5*SQRT((1+Paramètres!$B$4*(C25-1)+Paramètres!$B$5*(C25-1)^2)),0) -> 0 | I25: 2 | J25: 1 | K25: 0.3 | L25: =IF(M25=0,0,(E25+F25)/2) -> 2.5 | M25: 1 | N25: 4 | O25: 0 | P25: =IF(M25=0,"—",M25&"d"&N25&IF(O25=0,""," + "&O25)) -> 1d4 | Q25: =ROUND(INDEX(Catalogue!E$4:E$85,MATCH(A25,Catalogue!A$4:A$85,0))*(1+Paramètres!$B$4*(C25-1)+Paramètres!$B$5*(C25-1)^2),0) -> 2 | R25: =ROUND(INDEX(Catalogue!F$4:F$85,MATCH(A25,Catalogue!A$4:A$85,0))*(1+Paramètres!$B$4*(C25-1)+Paramètres!$B$5*(C25-1)^2),0) -> 3 | S25: =L25-AVERAGE(Q25:R25) -> 0 | T25: =IF(M25=0,IF(AND(N25=0,O25=0,E25=0,F25=0),"OK","ERREUR"),IF(AND(M25>=1,M25<=32,OR(N25=4,N25=6,N25=8,N25=10,N25=12,N25=20),O25>=0,E25=M25+O25,F25=M25*N25+O25),"OK","ERREUR")) -> OK | U25: =IF(M25>0,M25*(N25+1)/2+O25,0) -> 2.5 | V25: =IF(ABS(L25-U25)<0.001,"OK","ERREUR") -> OK
A26: ARM002 | B26: Poignard d'assassin | C26: 3 | D26: Légères | E26: =IF(M26=0,0,M26+O26) -> 2 | F26: =IF(M26=0,0,M26*N26+O26) -> 5 | G26: =ROUND(Catalogue!G5*SQRT((1+Paramètres!$B$4*(C26-1)+Paramètres!$B$5*(C26-1)^2)),0) -> 0 | H26: =ROUND(Catalogue!H5*SQRT((1+Paramètres!$B$4*(C26-1)+Paramètres!$B$5*(C26-1)^2)),0) -> 0 | I26: 2 | J26: 1 | K26: 0.3 | L26: =IF(M26=0,0,(E26+F26)/2) -> 3.5 | M26: 1 | N26: 4 | O26: 1 | P26: =IF(M26=0,"—",M26&"d"&N26&IF(O26=0,""," + "&O26)) -> 1d4 + 1 | Q26: =ROUND(INDEX(Catalogue!E$4:E$85,MATCH(A26,Catalogue!A$4:A$85,0))*(1+Paramètres!$B$4*(C26-1)+Paramètres!$B$5*(C26-1)^2),0) -> 3 | R26: =ROUND(INDEX(Catalogue!F$4:F$85,MATCH(A26,Catalogue!A$4:A$85,0))*(1+Paramètres!$B$4*(C26-1)+Paramètres!$B$5*(C26-1)^2),0) -> 4 | S26: =L26-AVERAGE(Q26:R26) -> 0 | T26: =IF(M26=0,IF(AND(N26=0,O26=0,E26=0,F26=0),"OK","ERREUR"),IF(AND(M26>=1,M26<=32,OR(N26=4,N26=6,N26=8,N26=10,N26=12,N26=20),O26>=0,E26=M26+O26,F26=M26*N26+O26),"OK","ERREUR")) -> OK | U26: =IF(M26>0,M26*(N26+1)/2+O26,0) -> 3.5 | V26: =IF(ABS(L26-U26)<0.001,"OK","ERREUR") -> OK
A27: ARM002 | B27: Poignard d'assassin | C27: 4 | D27: Légères | E27: =IF(M27=0,0,M27+O27) -> 2 | F27: =IF(M27=0,0,M27*N27+O27) -> 5 | G27: =ROUND(Catalogue!G5*SQRT((1+Paramètres!$B$4*(C27-1)+Paramètres!$B$5*(C27-1)^2)),0) -> 0 | H27: =ROUND(Catalogue!H5*SQRT((1+Paramètres!$B$4*(C27-1)+Paramètres!$B$5*(C27-1)^2)),0) -> 0 | I27: 2 | J27: 1 | K27: 0.3 | L27: =IF(M27=0,0,(E27+F27)/2) -> 3.5 | M27: 1 | N27: 4 | O27: 1 | P27: =IF(M27=0,"—",M27&"d"&N27&IF(O27=0,""," + "&O27)) -> 1d4 + 1 | Q27: =ROUND(INDEX(Catalogue!E$4:E$85,MATCH(A27,Catalogue!A$4:A$85,0))*(1+Paramètres!$B$4*(C27-1)+Paramètres!$B$5*(C27-1)^2),0) -> 3 | R27: =ROUND(INDEX(Catalogue!F$4:F$85,MATCH(A27,Catalogue!A$4:A$85,0))*(1+Paramètres!$B$4*(C27-1)+Paramètres!$B$5*(C27-1)^2),0) -> 4 | S27: =L27-AVERAGE(Q27:R27) -> 0 | T27: =IF(M27=0,IF(AND(N27=0,O27=0,E27=0,F27=0),"OK","ERREUR"),IF(AND(M27>=1,M27<=32,OR(N27=4,N27=6,N27=8,N27=10,N27=12,N27=20),O27>=0,E27=M27+O27,F27=M27*N27+O27),"OK","ERREUR")) -> OK | U27: =IF(M27>0,M27*(N27+1)/2+O27,0) -> 3.5 | V27: =IF(ABS(L27-U27)<0.001,"OK","ERREUR") -> OK
A28: ARM002 | B28: Poignard d'assassin | C28: 5 | D28: Légères | E28: =IF(M28=0,0,M28+O28) -> 2 | F28: =IF(M28=0,0,M28*N28+O28) -> 5 | G28: =ROUND(Catalogue!G5*SQRT((1+Paramètres!$B$4*(C28-1)+Paramètres!$B$5*(C28-1)^2)),0) -> 0 | H28: =ROUND(Catalogue!H5*SQRT((1+Paramètres!$B$4*(C28-1)+Paramètres!$B$5*(C28-1)^2)),0) -> 0 | I28: 2 | J28: 1 | K28: 0.3 | L28: =IF(M28=0,0,(E28+F28)/2) -> 3.5 | M28: 1 | N28: 4 | O28: 1 | P28: =IF(M28=0,"—",M28&"d"&N28&IF(O28=0,""," + "&O28)) -> 1d4 + 1 | Q28: =ROUND(INDEX(Catalogue!E$4:E$85,MATCH(A28,Catalogue!A$4:A$85,0))*(1+Paramètres!$B$4*(C28-1)+Paramètres!$B$5*(C28-1)^2),0) -> 3 | R28: =ROUND(INDEX(Catalogue!F$4:F$85,MATCH(A28,Catalogue!A$4:A$85,0))*(1+Paramètres!$B$4*(C28-1)+Paramètres!$B$5*(C28-1)^2),0) -> 5 | S28: =L28-AVERAGE(Q28:R28) -> -0.5 | T28: =IF(M28=0,IF(AND(N28=0,O28=0,E28=0,F28=0),"OK","ERREUR"),IF(AND(M28>=1,M28<=32,OR(N28=4,N28=6,N28=8,N28=10,N28=12,N28=20),O28>=0,E28=M28+O28,F28=M28*N28+O28),"OK","ERREUR")) -> OK | U28: =IF(M28>0,M28*(N28+1)/2+O28,0) -> 3.5 | V28: =IF(ABS(L28-U28)<0.001,"OK","ERREUR") -> OK
A29: ARM002 | B29: Poignard d'assassin | C29: 6 | D29: Légères | E29: =IF(M29=0,0,M29+O29) -> 3 | F29: =IF(M29=0,0,M29*N29+O29) -> 6 | G29: =ROUND(Catalogue!G5*SQRT((1+Paramètres!$B$4*(C29-1)+Paramètres!$B$5*(C29-1)^2)),0) -> 0 | H29: =ROUND(Catalogue!H5*SQRT((1+Paramètres!$B$4*(C29-1)+Paramètres!$B$5*(C29-1)^2)),0) -> 0 | I29: 2 | J29: 1 | K29: 0.3 | L29: =IF(M29=0,0,(E29+F29)/2) -> 4.5 | M29: 1 | N29: 4 | O29: 2 | P29: =IF(M29=0,"—",M29&"d"&N29&IF(O29=0,""," + "&O29)) -> 1d4 + 2 | Q29: =ROUND(INDEX(Catalogue!E$4:E$85,MATCH(A29,Catalogue!A$4:A$85,0))*(1+Paramètres!$B$4*(C29-1)+Paramètres!$B$5*(C29-1)^2),0) -> 4 | R29: =ROUND(INDEX(Catalogue!F$4:F$85,MATCH(A29,Catalogue!A$4:A$85,0))*(1+Paramètres!$B$4*(C29-1)+Paramètres!$B$5*(C29-1)^2),0) -> 6 | S29: =L29-AVERAGE(Q29:R29) -> -0.5 | T29: =IF(M29=0,IF(AND(N29=0,O29=0,E29=0,F29=0),"OK","ERREUR"),IF(AND(M29>=1,M29<=32,OR(N29=4,N29=6,N29=8,N29=10,N29=12,N29=20),O29>=0,E29=M29+O29,F29=M29*N29+O29),"OK","ERREUR")) -> OK | U29: =IF(M29>0,M29*(N29+1)/2+O29,0) -> 4.5 | V29: =IF(ABS(L29-U29)<0.001,"OK","ERREUR") -> OK
A30: ARM002 | B30: Poignard d'assassin | C30: 7 | D30: Légères | E30: =IF(M30=0,0,M30+O30) -> 4 | F30: =IF(M30=0,0,M30*N30+O30) -> 7 | G30: =ROUND(Catalogue!G5*SQRT((1+Paramètres!$B$4*(C30-1)+Paramètres!$B$5*(C30-1)^2)),0) -> 0 | H30: =ROUND(Catalogue!H5*SQRT((1+Paramètres!$B$4*(C30-1)+Paramètres!$B$5*(C30-1)^2)),0) -> 0 | I30: 2 | J30: 1 | K30: 0.3 | L30: =IF(M30=0,0,(E30+F30)/2) -> 5.5 | M30: 1 | N30: 4 | O30: 3 | P30: =IF(M30=0,"—",M30&"d"&N30&IF(O30=0,""," + "&O30)) -> 1d4 + 3 | Q30: =ROUND(INDEX(Catalogue!E$4:E$85,MATCH(A30,Catalogue!A$4:A$85,0))*(1+Paramètres!$B$4*(C30-1)+Paramètres!$B$5*(C30-1)^2),0) -> 4 | R30: =ROUND(INDEX(Catalogue!F$4:F$85,MATCH(A30,Catalogue!A$4:A$85,0))*(1+Paramètres!$B$4*(C30-1)+Paramètres!$B$5*(C30-1)^2),0) -> 7 | S30: =L30-AVERAGE(Q30:R30) -> 0 | T30: =IF(M30=0,IF(AND(N30=0,O30=0,E30=0,F30=0),"OK","ERREUR"),IF(AND(M30>=1,M30<=32,OR(N30=4,N30=6,N30=8,N30=10,N30=12,N30=20),O30>=0,E30=M30+O30,F30=M30*N30+O30),"OK","ERREUR")) -> OK | U30: =IF(M30>0,M30*(N30+1)/2+O30,0) -> 5.5 | V30: =IF(ABS(L30-U30)<0.001,"OK","ERREUR") -> OK
A31: ARM002 | B31: Poignard d'assassin | C31: 8 | D31: Légères | E31: =IF(M31=0,0,M31+O31) -> 5 | F31: =IF(M31=0,0,M31*N31+O31) -> 8 | G31: =ROUND(Catalogue!G5*SQRT((1+Paramètres!$B$4*(C31-1)+Paramètres!$B$5*(C31-1)^2)),0) -> 0 | H31: =ROUND(Catalogue!H5*SQRT((1+Paramètres!$B$4*(C31-1)+Paramètres!$B$5*(C31-1)^2)),0) -> 0 | I31: 2 | J31: 1 | K31: 0.3 | L31: =IF(M31=0,0,(E31+F31)/2) -> 6.5 | M31: 1 | N31: 4 | O31: 4 | P31: =IF(M31=0,"—",M31&"d"&N31&IF(O31=0,""," + "&O31)) -> 1d4 + 4 | Q31: =ROUND(INDEX(Catalogue!E$4:E$85,MATCH(A31,Catalogue!A$4:A$85,0))*(1+Paramètres!$B$4*(C31-1)+Paramètres!$B$5*(C31-1)^2),0) -> 5 | R31: =ROUND(INDEX(Catalogue!F$4:F$85,MATCH(A31,Catalogue!A$4:A$85,0))*(1+Paramètres!$B$4*(C31-1)+Paramètres!$B$5*(C31-1)^2),0) -> 8 | S31: =L31-AVERAGE(Q31:R31) -> 0 | T31: =IF(M31=0,IF(AND(N31=0,O31=0,E31=0,F31=0),"OK","ERREUR"),IF(AND(M31>=1,M31<=32,OR(N31=4,N31=6,N31=8,N31=10,N31=12,N31=20),O31>=0,E31=M31+O31,F31=M31*N31+O31),"OK","ERREUR")) -> OK | U31: =IF(M31>0,M31*(N31+1)/2+O31,0) -> 6.5 | V31: =IF(ABS(L31-U31)<0.001,"OK","ERREUR") -> OK
A32: ARM002 | B32: Poignard d'assassin | C32: 9 | D32: Légères | E32: =IF(M32=0,0,M32+O32) -> 6 | F32: =IF(M32=0,0,M32*N32+O32) -> 9 | G32: =ROUND(Catalogue!G5*SQRT((1+Paramètres!$B$4*(C32-1)+Paramètres!$B$5*(C32-1)^2)),0) -> 0 | H32: =ROUND(Catalogue!H5*SQRT((1+Paramètres!$B$4*(C32-1)+Paramètres!$B$5*(C32-1)^2)),0) -> 0 | I32: 2 | J32: 1 | K32: 0.3 | L32: =IF(M32=0,0,(E32+F32)/2) -> 7.5 | M32: 1 | N32: 4 | O32: 5 | P32: =IF(M32=0,"—",M32&"d"&N32&IF(O32=0,""," + "&O32)) -> 1d4 + 5 | Q32: =ROUND(INDEX(Catalogue!E$4:E$85,MATCH(A32,Catalogue!A$4:A$85,0))*(1+Paramètres!$B$4*(C32-1)+Paramètres!$B$5*(C32-1)^2),0) -> 6 | R32: =ROUND(INDEX(Catalogue!F$4:F$85,MATCH(A32,Catalogue!A$4:A$85,0))*(1+Paramètres!$B$4*(C32-1)+Paramètres!$B$5*(C32-1)^2),0) -> 9 | S32: =L32-AVERAGE(Q32:R32) -> 0 | T32: =IF(M32=0,IF(AND(N32=0,O32=0,E32=0,F32=0),"OK","ERREUR"),IF(AND(M32>=1,M32<=32,OR(N32=4,N32=6,N32=8,N32=10,N32=12,N32=20),O32>=0,E32=M32+O32,F32=M32*N32+O32),"OK","ERREUR")) -> OK | U32: =IF(M32>0,M32*(N32+1)/2+O32,0) -> 7.5 | V32: =IF(ABS(L32-U32)<0.001,"OK","ERREUR") -> OK
A33: ARM002 | B33: Poignard d'assassin | C33: 10 | D33: Légères | E33: =IF(M33=0,0,M33+O33) -> 7 | F33: =IF(M33=0,0,M33*N33+O33) -> 10 | G33: =ROUND(Catalogue!G5*SQRT((1+Paramètres!$B$4*(C33-1)+Paramètres!$B$5*(C33-1)^2)),0) -> 0 | H33: =ROUND(Catalogue!H5*SQRT((1+Paramètres!$B$4*(C33-1)+Paramètres!$B$5*(C33-1)^2)),0) -> 0 | I33: 2 | J33: 1 | K33: 0.3 | L33: =IF(M33=0,0,(E33+F33)/2) -> 8.5 | M33: 1 | N33: 4 | O33: 6 | P33: =IF(M33=0,"—",M33&"d"&N33&IF(O33=0,""," + "&O33)) -> 1d4 + 6 | Q33: =ROUND(INDEX(Catalogue!E$4:E$85,MATCH(A33,Catalogue!A$4:A$85,0))*(1+Paramètres!$B$4*(C33-1)+Paramètres!$B$5*(C33-1)^2),0) -> 7 | R33: =ROUND(INDEX(Catalogue!F$4:F$85,MATCH(A33,Catalogue!A$4:A$85,0))*(1+Paramètres!$B$4*(C33-1)+Paramètres!$B$5*(C33-1)^2),0) -> 10 | S33: =L33-AVERAGE(Q33:R33) -> 0 | T33: =IF(M33=0,IF(AND(N33=0,O33=0,E33=0,F33=0),"OK","ERREUR"),IF(AND(M33>=1,M33<=32,OR(N33=4,N33=6,N33=8,N33=10,N33=12,N33=20),O33>=0,E33=M33+O33,F33=M33*N33+O33),"OK","ERREUR")) -> OK | U33: =IF(M33>0,M33*(N33+1)/2+O33,0) -> 8.5 | V33: =IF(ABS(L33-U33)<0.001,"OK","ERREUR") -> OK
A34: ARM002 | B34: Poignard d'assassin | C34: 11 | D34: Légères | E34: =IF(M34=0,0,M34+O34) -> 7 | F34: =IF(M34=0,0,M34*N34+O34) -> 10 | G34: =ROUND(Catalogue!G5*SQRT((1+Paramètres!$B$4*(C34-1)+Paramètres!$B$5*(C34-1)^2)),0) -> 0 | H34: =ROUND(Catalogue!H5*SQRT((1+Paramètres!$B$4*(C34-1)+Paramètres!$B$5*(C34-1)^2)),0) -> 0 | I34: 2 | J34: 1 | K34: 0.3 | L34: =IF(M34=0,0,(E34+F34)/2) -> 8.5 | M34: 1 | N34: 4 | O34: 6 | P34: =IF(M34=0,"—",M34&"d"&N34&IF(O34=0,""," + "&O34)) -> 1d4 + 6 | Q34: =ROUND(INDEX(Catalogue!E$4:E$85,MATCH(A34,Catalogue!A$4:A$85,0))*(1+Paramètres!$B$4*(C34-1)+Paramètres!$B$5*(C34-1)^2),0) -> 7 | R34: =ROUND(INDEX(Catalogue!F$4:F$85,MATCH(A34,Catalogue!A$4:A$85,0))*(1+Paramètres!$B$4*(C34-1)+Paramètres!$B$5*(C34-1)^2),0) -> 11 | S34: =L34-AVERAGE(Q34:R34) -> -0.5 | T34: =IF(M34=0,IF(AND(N34=0,O34=0,E34=0,F34=0),"OK","ERREUR"),IF(AND(M34>=1,M34<=32,OR(N34=4,N34=6,N34=8,N34=10,N34=12,N34=20),O34>=0,E34=M34+O34,F34=M34*N34+O34),"OK","ERREUR")) -> OK | U34: =IF(M34>0,M34*(N34+1)/2+O34,0) -> 8.5 | V34: =IF(ABS(L34-U34)<0.001,"OK","ERREUR") -> OK
A35: ARM002 | B35: Poignard d'assassin | C35: 12 | D35: Légères | E35: =IF(M35=0,0,M35+O35) -> 9 | F35: =IF(M35=0,0,M35*N35+O35) -> 12 | G35: =ROUND(Catalogue!G5*SQRT((1+Paramètres!$B$4*(C35-1)+Paramètres!$B$5*(C35-1)^2)),0) -> 0 | H35: =ROUND(Catalogue!H5*SQRT((1+Paramètres!$B$4*(C35-1)+Paramètres!$B$5*(C35-1)^2)),0) -> 0 | I35: 2 | J35: 1 | K35: 0.3 | L35: =IF(M35=0,0,(E35+F35)/2) -> 10.5 | M35: 1 | N35: 4 | O35: 8 | P35: =IF(M35=0,"—",M35&"d"&N35&IF(O35=0,""," + "&O35)) -> 1d4 + 8 | Q35: =ROUND(INDEX(Catalogue!E$4:E$85,MATCH(A35,Catalogue!A$4:A$85,0))*(1+Paramètres!$B$4*(C35-1)+Paramètres!$B$5*(C35-1)^2),0) -> 8 | R35: =ROUND(INDEX(Catalogue!F$4:F$85,MATCH(A35,Catalogue!A$4:A$85,0))*(1+Paramètres!$B$4*(C35-1)+Paramètres!$B$5*(C35-1)^2),0) -> 12 | S35: =L35-AVERAGE(Q35:R35) -> 0.5 | T35: =IF(M35=0,IF(AND(N35=0,O35=0,E35=0,F35=0),"OK","ERREUR"),IF(AND(M35>=1,M35<=32,OR(N35=4,N35=6,N35=8,N35=10,N35=12,N35=20),O35>=0,E35=M35+O35,F35=M35*N35+O35),"OK","ERREUR")) -> OK | U35: =IF(M35>0,M35*(N35+1)/2+O35,0) -> 10.5 | V35: =IF(ABS(L35-U35)<0.001,"OK","ERREUR") -> OK
A36: ARM002 | B36: Poignard d'assassin | C36: 13 | D36: Légères | E36: =IF(M36=0,0,M36+O36) -> 9 | F36: =IF(M36=0,0,M36*N36+O36) -> 14 | G36: =ROUND(Catalogue!G5*SQRT((1+Paramètres!$B$4*(C36-1)+Paramètres!$B$5*(C36-1)^2)),0) -> 0 | H36: =ROUND(Catalogue!H5*SQRT((1+Paramètres!$B$4*(C36-1)+Paramètres!$B$5*(C36-1)^2)),0) -> 0 | I36: 2 | J36: 1 | K36: 0.3 | L36: =IF(M36=0,0,(E36+F36)/2) -> 11.5 | M36: 1 | N36: 6 | O36: 8 | P36: =IF(M36=0,"—",M36&"d"&N36&IF(O36=0,""," + "&O36)) -> 1d6 + 8 | Q36: =ROUND(INDEX(Catalogue!E$4:E$85,MATCH(A36,Catalogue!A$4:A$85,0))*(1+Paramètres!$B$4*(C36-1)+Paramètres!$B$5*(C36-1)^2),0) -> 9 | R36: =ROUND(INDEX(Catalogue!F$4:F$85,MATCH(A36,Catalogue!A$4:A$85,0))*(1+Paramètres!$B$4*(C36-1)+Paramètres!$B$5*(C36-1)^2),0) -> 14 | S36: =L36-AVERAGE(Q36:R36) -> 0 | T36: =IF(M36=0,IF(AND(N36=0,O36=0,E36=0,F36=0),"OK","ERREUR"),IF(AND(M36>=1,M36<=32,OR(N36=4,N36=6,N36=8,N36=10,N36=12,N36=20),O36>=0,E36=M36+O36,F36=M36*N36+O36),"OK","ERREUR")) -> OK | U36: =IF(M36>0,M36*(N36+1)/2+O36,0) -> 11.5 | V36: =IF(ABS(L36-U36)<0.001,"OK","ERREUR") -> OK
A37: ARM002 | B37: Poignard d'assassin | C37: 14 | D37: Légères | E37: =IF(M37=0,0,M37+O37) -> 10 | F37: =IF(M37=0,0,M37*N37+O37) -> 15 | G37: =ROUND(Catalogue!G5*SQRT((1+Paramètres!$B$4*(C37-1)+Paramètres!$B$5*(C37-1)^2)),0) -> 0 | H37: =ROUND(Catalogue!H5*SQRT((1+Paramètres!$B$4*(C37-1)+Paramètres!$B$5*(C37-1)^2)),0) -> 0 | I37: 2 | J37: 1 | K37: 0.3 | L37: =IF(M37=0,0,(E37+F37)/2) -> 12.5 | M37: 1 | N37: 6 | O37: 9 | P37: =IF(M37=0,"—",M37&"d"&N37&IF(O37=0,""," + "&O37)) -> 1d6 + 9 | Q37: =ROUND(INDEX(Catalogue!E$4:E$85,MATCH(A37,Catalogue!A$4:A$85,0))*(1+Paramètres!$B$4*(C37-1)+Paramètres!$B$5*(C37-1)^2),0) -> 10 | R37: =ROUND(INDEX(Catalogue!F$4:F$85,MATCH(A37,Catalogue!A$4:A$85,0))*(1+Paramètres!$B$4*(C37-1)+Paramètres!$B$5*(C37-1)^2),0) -> 15 | S37: =L37-AVERAGE(Q37:R37) -> 0 | T37: =IF(M37=0,IF(AND(N37=0,O37=0,E37=0,F37=0),"OK","ERREUR"),IF(AND(M37>=1,M37<=32,OR(N37=4,N37=6,N37=8,N37=10,N37=12,N37=20),O37>=0,E37=M37+O37,F37=M37*N37+O37),"OK","ERREUR")) -> OK | U37: =IF(M37>0,M37*(N37+1)/2+O37,0) -> 12.5 | V37: =IF(ABS(L37-U37)<0.001,"OK","ERREUR") -> OK
A38: ARM002 | B38: Poignard d'assassin | C38: 15 | D38: Légères | E38: =IF(M38=0,0,M38+O38) -> 11 | F38: =IF(M38=0,0,M38*N38+O38) -> 17 | G38: =ROUND(Catalogue!G5*SQRT((1+Paramètres!$B$4*(C38-1)+Paramètres!$B$5*(C38-1)^2)),0) -> 0 | H38: =ROUND(Catalogue!H5*SQRT((1+Paramètres!$B$4*(C38-1)+Paramètres!$B$5*(C38-1)^2)),0) -> 0 | I38: 2 | J38: 1 | K38: 0.3 | L38: =IF(M38=0,0,(E38+F38)/2) -> 14 | M38: 2 | N38: 4 | O38: 9 | P38: =IF(M38=0,"—",M38&"d"&N38&IF(O38=0,""," + "&O38)) -> 2d4 + 9 | Q38: =ROUND(INDEX(Catalogue!E$4:E$85,MATCH(A38,Catalogue!A$4:A$85,0))*(1+Paramètres!$B$4*(C38-1)+Paramètres!$B$5*(C38-1)^2),0) -> 11 | R38: =ROUND(INDEX(Catalogue!F$4:F$85,MATCH(A38,Catalogue!A$4:A$85,0))*(1+Paramètres!$B$4*(C38-1)+Paramètres!$B$5*(C38-1)^2),0) -> 17 | S38: =L38-AVERAGE(Q38:R38) -> 0 | T38: =IF(M38=0,IF(AND(N38=0,O38=0,E38=0,F38=0),"OK","ERREUR"),IF(AND(M38>=1,M38<=32,OR(N38=4,N38=6,N38=8,N38=10,N38=12,N38=20),O38>=0,E38=M38+O38,F38=M38*N38+O38),"OK","ERREUR")) -> OK | U38: =IF(M38>0,M38*(N38+1)/2+O38,0) -> 14 | V38: =IF(ABS(L38-U38)<0.001,"OK","ERREUR") -> OK
A39: ARM002 | B39: Poignard d'assassin | C39: 16 | D39: Légères | E39: =IF(M39=0,0,M39+O39) -> 13 | F39: =IF(M39=0,0,M39*N39+O39) -> 19 | G39: =ROUND(Catalogue!G5*SQRT((1+Paramètres!$B$4*(C39-1)+Paramètres!$B$5*(C39-1)^2)),0) -> 0 | H39: =ROUND(Catalogue!H5*SQRT((1+Paramètres!$B$4*(C39-1)+Paramètres!$B$5*(C39-1)^2)),0) -> 0 | I39: 2 | J39: 1 | K39: 0.3 | L39: =IF(M39=0,0,(E39+F39)/2) -> 16 | M39: 2 | N39: 4 | O39: 11 | P39: =IF(M39=0,"—",M39&"d"&N39&IF(O39=0,""," + "&O39)) -> 2d4 + 11 | Q39: =ROUND(INDEX(Catalogue!E$4:E$85,MATCH(A39,Catalogue!A$4:A$85,0))*(1+Paramètres!$B$4*(C39-1)+Paramètres!$B$5*(C39-1)^2),0) -> 13 | R39: =ROUND(INDEX(Catalogue!F$4:F$85,MATCH(A39,Catalogue!A$4:A$85,0))*(1+Paramètres!$B$4*(C39-1)+Paramètres!$B$5*(C39-1)^2),0) -> 19 | S39: =L39-AVERAGE(Q39:R39) -> 0 | T39: =IF(M39=0,IF(AND(N39=0,O39=0,E39=0,F39=0),"OK","ERREUR"),IF(AND(M39>=1,M39<=32,OR(N39=4,N39=6,N39=8,N39=10,N39=12,N39=20),O39>=0,E39=M39+O39,F39=M39*N39+O39),"OK","ERREUR")) -> OK | U39: =IF(M39>0,M39*(N39+1)/2+O39,0) -> 16 | V39: =IF(ABS(L39-U39)<0.001,"OK","ERREUR") -> OK
A40: ARM002 | B40: Poignard d'assassin | C40: 17 | D40: Légères | E40: =IF(M40=0,0,M40+O40) -> 14 | F40: =IF(M40=0,0,M40*N40+O40) -> 21 | G40: =ROUND(Catalogue!G5*SQRT((1+Paramètres!$B$4*(C40-1)+Paramètres!$B$5*(C40-1)^2)),0) -> 0 | H40: =ROUND(Catalogue!H5*SQRT((1+Paramètres!$B$4*(C40-1)+Paramètres!$B$5*(C40-1)^2)),0) -> 0 | I40: 2 | J40: 1 | K40: 0.3 | L40: =IF(M40=0,0,(E40+F40)/2) -> 17.5 | M40: 1 | N40: 8 | O40: 13 | P40: =IF(M40=0,"—",M40&"d"&N40&IF(O40=0,""," + "&O40)) -> 1d8 + 13 | Q40: =ROUND(INDEX(Catalogue!E$4:E$85,MATCH(A40,Catalogue!A$4:A$85,0))*(1+Paramètres!$B$4*(C40-1)+Paramètres!$B$5*(C40-1)^2),0) -> 14 | R40: =ROUND(INDEX(Catalogue!F$4:F$85,MATCH(A40,Catalogue!A$4:A$85,0))*(1+Paramètres!$B$4*(C40-1)+Paramètres!$B$5*(C40-1)^2),0) -> 21 | S40: =L40-AVERAGE(Q40:R40) -> 0 | T40: =IF(M40=0,IF(AND(N40=0,O40=0,E40=0,F40=0),"OK","ERREUR"),IF(AND(M40>=1,M40<=32,OR(N40=4,N40=6,N40=8,N40=10,N40=12,N40=20),O40>=0,E40=M40+O40,F40=M40*N40+O40),"OK","ERREUR")) -> OK | U40: =IF(M40>0,M40*(N40+1)/2+O40,0) -> 17.5 | V40: =IF(ABS(L40-U40)<0.001,"OK","ERREUR") -> OK
...

Sheet Raretés
A1: Raretés et codes couleurs
A2: Niveau d'objet immuable. Les couleurs expriment la rareté; affixes/runes portent la diversité, sans multiplication WD automatique.
A3: Rareté | B3: HEX | C3: WD de rareté (proposé) | D3: Nb affixes | E3: Chasses de rune | F3: Propriété | G3: Origine | H3: Contraintes
A4: Commun | B4: #92999F | C4: 1 | D4: 0 | E4: 0 | F4: Aucun affixe standard | G4: Butin courant | H4: Niveau fixe, dégâts par dés
A5: Rare | B5: #42A75B | C5: 1 | D5: 1 | E5: 1 | F5: 1 affixe | G5: Butin peu fréquent | H5: Rune optionnelle; dégâts sans multiplicateur automatique
A6: Épique | B6: #368DDF | C6: 1 | D6: 2 | E6: 1 | F6: 2 affixes | G6: Butin exceptionnel | H6: Affixes sans effet cumulé excessif
A7: Légendaire | B7: #9B59D0 | C7: 1 | D7: 3 | E7: 2 | F7: 3 affixes | G7: Butin très rare | H7: 2 runes maximum
A8: Unique | B8: #D4A23A | C8: 1 | D8: 0 | E8: 0 | F8: Propriétés fixes / définies par objet | G8: Quête ou boss | H8: Rareté narrative, puissance non garantie
A11: Principes
A12: Rareté≠niveau | B12: Une arme Rare N4 ne gagne jamais de niveau ; le porteur peut s'équiper d'un objet > son niveau avec malus.
A13: Unique≠suprême | B13: Le mécanisme narratif prévaut; certains objets uniques sont de niveau bas.
A14: Affixes | B14: Petits bonus de précision, résistance, stats, mana, critique, statut conditionnel.
A15: Raretés demandées | B15: Aucun palier « Peu commun » dans cette version; peut être ajouté sans rompre les IDs.
A16: Production | B16: Couleurs et slots sont PROPOSÉS, pas une fonctionnalité déjà confirmée du jeu.

Sheet Classes
A1: Affinités des six classes
A2: Les préférences guident les talents, l'équilibrage et les drops — aucune interdiction rigide de classe proposée.
A3: Classe | B3: Branches canoniques | C3: Armement prioritaire | D3: Exemples emblématiques | E3: Alternatives | F3: Attributs dominants | G3: Synergies
A4: Guerrier | B4: Gardien / Brise-ligne / Maître d'armes | C4: Épée+écu, masse+écu, grande hache, hallebarde | D4: Épée longue, marteau à deux mains | E4: Lances, arbalète légère | F4: Force; Constitution | G4: Garde/contre-attaque/puissance WD
A5: Voleur | B5: Assassin / Ombre / Saboteur | C5: Deux dagues, stylet, rapière, couteau de jet | D5: Poignard d'assassin, main-gauche | E5: Arc court, arbalète légère | F5: Dextérité | G5: Critique positionnel, saignement, discrétion
A6: Rôdeur | B6: Tireur / Chasseur / Éclaireur | C6: Arc long/composite, arbalète, lance, javelot | D6: Arc recourbé, épée courte | E6: Rapière, fronde, poignard | F6: Dextérité; Force optionnelle | G6: Portée/LOS/mobilité/ennemi juré
A7: Mage | B7: Évocateur / Arcaniste / Tisseur de surfaces | C7: Baguettes élémentaires, bâtons arcaniques, orbe | D7: Bâton élémentaire, baguette+orbe | E7: Dague légère de secours | F7: Intelligence | G7: Affinité élémentaire/surfaces/mana
A8: Prêtre | B8: Restauration / Protection / Exorcisme | C8: Masse+égide, marteau, sceptre sacré, bouclier runique | D8: Masse d'armes, sceptre sacré | E8: Bâton rituel, arbalète légère | F8: Sagesse; Force optionnelle | G8: Protection/soins/contre morts-vivants
A9: Alchimiste | B9: Grenadier / Apothicaire / Transmutateur | C9: Arbalète légère, dards, couteau, focus secondaire | D9: Sarbacane, arbalète légère, hachette | E9: Dague de jet, bâton rituel | F9: Dextérité; Intelligence | G9: Huiles/poisons/bombes/recettes

Sheet Améliorations
A1: Forge · Alchimie · Runes
A2: Règle ARM-001 : aucune recette ne modifie ItemLevel. Les améliorations changent uniquement les propriétés/bonus d'une instance.
A3: Code | B3: Discipline | C3: Recette | D3: Durée | E3: Effet | F3: Cibles | G3: Ingrédients conceptuels | H3: Palier | I3: Limites / exclusions | J3: Compatibilité runtime
A4: FOR01 | B4: Forge | C4: Affûtage de lame | D4: Permanent | E4: +1 précision (une seule fois) | F4: Lame tranchante/perforante | G4: Pierre d'aiguisage + fer | H4: N1+ | I4: 1 modification d'affûtage par arme | J4: Ne change pas Min/Max
A5: FOR02 | B5: Forge | C5: Trempe simple | D5: Permanent | E5: +1 dégâts plats (sans changement de niveau) | F5: Armes métalliques | G5: Minerai de fer + charbon + essence de forge | H5: N1+ | I5: Non cumulable ; remplacée par Trempe supérieure | J5: Ajoute +1 au FlatDamageBonus effectif
A6: FOR03 | B6: Forge | C6: Trempe supérieure | D6: Permanent | E6: +2 dégâts plats ; remplace Trempe simple | F6: Armes métalliques | G6: Acier raffiné + cœur incandescent | H6: N8+ | I6: Une seule trempe active par objet | J6: Ajoute +2 au FlatDamageBonus, pas de level-up
A7: FOR04 | B7: Forge | C7: Renforcement d'écu | D7: Permanent | E7: +5% armure physique | F7: Boucliers | G7: Rivets + plaque acier | H7: N3+ | I7: Un seul renforcement | J7: Sur protection finale de l'écu
A8: FOR05 | B8: Forge | C8: Bordure runique | D8: Permanent | E8: Ajoute 1 chasse dans limite de rareté | F8: Rare/Épique/Légendaire uniquement | G8: Poudre de rune + métal lunaire | H8: N8+ | I8: Max 1/1/2 chasses selon rareté | J8: Pas de chasses supplémentaires sur Commun
A9: FOR06 | B9: Forge | C9: Rééquilibrage d'arme | D9: Permanent | E9: +1 précision / -5% dégâts théoriques | F9: Armes lourdes | G9: Contrepoids + lingot | H9: N5+ | I9: Exclusif de garde renforcée | J9: Choix, pas bonus gratuit
A10: ALC01 | B10: Alchimie | C10: Huile d'affûtage | D10: Temporaire | E10: +5% dégâts tranchants | F10: Armes tranchantes | G10: Huile claire + pierre pilée | H10: N1+ | I10: 3 combats ou 10 coups réussis | J10: Une huile active par arme
A11: ALC02 | B11: Alchimie | C11: Huile perforante | D11: Temporaire | E11: +5% dégâts perforants | F11: Armes perforantes | G11: Huile claire + épine de fer | H11: N3+ | I11: 3 combats ou 10 coups réussis | J11: Une huile active par arme
A12: ALC03 | B12: Alchimie | C12: Pâte de percussion | D12: Temporaire | E12: +5% dégâts contondants | F12: Armes contondantes | G12: Graisse + poudre de quartz | H12: N3+ | I12: 3 combats ou 10 coups réussis | J12: Une huile active par arme
A13: ALC04 | B13: Alchimie | C13: Poison de lame | D13: Temporaire | E13: Chance limitée d'appliquer Poison | F13: Lames/dards | G13: Venin + distillat végétal | H13: N2+ | I13: 3 combats ou 10 coups réussis | J13: Passe par statuts et ArmorGate existants
A14: ALC05 | B14: Alchimie | C14: Résine incendiaire | D14: Temporaire | E14: Dégâts de Feu additionnels faibles | F14: Arme compatible | G14: Résine + soufre | H14: N5+ | I14: 3 combats ou 10 coups réussis | J14: Ne change pas le DamageType principal
... A24: FOR07 | B24: Forge | C24: Reforge d'artefact unique | D24: Permanent | E24: Effet spécifique prédéfini ; niveau inchangé | F24: Unique scénarisé | G24: Fragment de relique + métal ancien | H24: N12+ | I24: Un effet de reforge par artefact, défini à l'authoring | J24: Ne modifie pas ItemLevel ni l'identité Unique

Sheet Uniques
A1: Douze objets uniques nommés
A2: Concepts narratifs : propriétés fixes, non tirées aléatoirement. Les statuts et dégâts doivent réutiliser le moteur de combat.
A3: ID | B3: Nom propre | C3: Archétype de base | D3: Niveau natif | E3: Classe signature | F3: Identité | G3: Pouvoir spécifique proposé | H3: Acquisition | I3: Chasses proposées
A4: UNI001 | B4: Lame des Veilleurs | C4: Épée droite | D4: 5 | E4: Guerrier | F4: Rarement portée par les sentinelles | G4: Sur parade réussie, bonus de garde pour 1 tour | H4: Bastion oublié | I4: 1
A5: UNI002 | B5: Brise-Sceau | C5: Marteau à deux mains | D5: 11 | E5: Guerrier | F5: Perce les anciennes protections | G5: Bonus contre armure physique (effect séparé) | H5: Boss du gardien | I5: 0
A6: UNI003 | B6: Murmure des Ombres | C6: Poignard d'assassin | D6: 7 | E6: Voleur | F6: Lame silencieuse | G6: Premier coup depuis Caché : chance de saignement | H6: Crypte du voleur | I6: 1
A7: UNI004 | B7: Dernier Mot | C7: Main-gauche | D7: 12 | E7: Voleur | F7: Dague de contre-attaque | G7: Parade/riposte conditionnelle si talent actif | H7: Énigme des miroirs | I7: 0
A8: UNI005 | B8: Corde de l'Horizon | C8: Arc long | D8: 9 | E8: Rôdeur | F8: Arc de forêt ancienne | G8: Bonus de précision au-delà de 3 cases | H8: Autel des pisteurs | I8: 1
A9: UNI006 | B9: Serre de la Chasse | C9: Javelot | D9: 14 | E9: Rôdeur | F9: Javelot des grands chasseurs | G9: Bonus contre ennemi juré | H9: Chasse légendaire | I9: 1
A10: UNI007 | B10: Cendre-Mémoire | C10: Bâton élémentaire | D10: 10 | E10: Mage | F10: Bâton à rune instable | G10: Un seul élément d'affinité choisi de façon persistante | H10: Bibliothèque scellée | I10: 1
A11: UNI008 | B11: Œil d'Azur | C11: Orbe arcanique | D11: 16 | E11: Mage | F11: Orbe de concentration | G11: Bonus de mana et contrôle des surfaces | H11: Sanctuaire arcanique | I11: 0
A12: UNI009 | B12: Aube Silencieuse | C12: Sceptre sacré | D12: 12 | E12: Prêtre | F12: Reliquaire des exorcistes | G12: Contre morts-vivants : effet Holy conditionnel | H12: Temple enfoui | I12: 1
A13: UNI010 | B13: Rempart des Justes | C13: Égide sacrée | D13: 17 | E13: Prêtre | F13: Bouclier votif | G13: Bonus de résistance sacrée au groupe (talent requis) | H13: Boss du temple | I13: 1
A14: UNI011 | B14: Catalyseur d'Argent | C14: Arbalète légère | D14: 8 | E14: Alchimiste | F14: Arbalète alchimique | G14: Effet temporaire amplifié des huiles appliquées | H14: Laboratoire secret | I14: 1
A15: UNI012 | B15: L'Alambic Gris | C15: Grimoire focaliseur | D15: 15 | E15: Alchimiste | F15: Carnet de transmutation | G15: Bonus à certaines recettes, sans attaque propre | H15: Quête du maître alchimiste | I15: 0

Sheet Paramètres
A1: ARMEMENT01 — Cibles d'équilibrage (dés fixes au butin)
A2: La courbe de progression sert à choisir les profils ; la formule de dés M:N:O est la source réelle des dégâts. Modifier k1/k2 ne change pas automatiquement les dés.
A3: Paramètre | B3: Valeur | C3: Rôle
A4: Croissance par niveau d'OBJET k1 | B4: 0.11 | C4: Coefficient par niveau
A5: Accélération par niveau d'OBJET k2 | B5: 0.016 | C5: Accélération modérée des dégâts
A6: Niveau maximum | B6: 20 | C6: Plafond de progression
A7: PA par personnage / tour | B7: 4 | C7: Autorité existante du projet, rappel
A8: Poids d'arme | B8: kg | C8: Poids catalogue conservé, ne dépend pas du niveau
A9: Attributs / rareté / qualité de forge | B9: Hors formule | C9: Affixes, précision et effets conditionnels restent séparés du WD.
A10: Malus de précision / niveau manquant | B10: 2 | C10: −2 précision par niveau d'objet au-dessus du porteur, plafond B13 (proposé)
A11: Perte de puissance / niveau manquant | B11: 0.1 | C11: −10% WD + protection pour chaque niveau manquant (proposé)
A12: Puissance et protection minimum | B12: 0.5 | C12: Plancher 50% (proposé)
A13: Malus de précision maximal | B13: 10 | C13: Malus plafonné à −10 (proposé)
A14: Écart maximum équipable (proposé) | B14: 3 | C14: Au-delà : équipement refusé, sous réserve de validation (anti-abus)
A15: Niveau d'objet fixe | B15: OUI | C15: Aucune forge/rune/huile ne modifie ItemLevel
A16: Dés autorisés | B16: d4, d6, d8, d10, d12, d20 | C16: Sommer NdM lancers indépendants + K; ne pas substituer RandRange(Min,Max).
A17: Rareté et dégâts | B17: Aucun multiplicateur automatique | C17: Les affixes/runes agissent via modificateurs et statuts identifiés.
A18: Source des dés | B18: Niveaux 1-20 : M/N/O | C18: Les colonnes Q/R/S montrent les cibles historiques (non autoritaires).
A19: Mode Dice (contrat ARMEMENT01.2) | B19: Opt-in non implémenté | C19: Activer explicitement uniquement sur une attaque convertie; les profils legacy restent uniformes.
A20: Nb de dés max proposé | B20: 32 | C20: Protection contre abus de données. Le catalogue v0.3 utilise au plus 6 dés.
A21: Bonus K inclus | B21: OUI | C21: Ne jamais dupliquer la constante des dés dans FlatDamageBonus ou SourceDamageBonus.
A22: Validation données | B22: Niveaux 1-20!T:V | C22: Vérifications calculées pour les 1640 profils.

Sheet Implémentation UE5
A1: Intégration Unreal Engine 5.5.4
A2: ARMEMENT01.2 — schéma multi-dés opt-in, sans modification du moteur UE5 dans ce jalon.
A3: Statut | B3: Point d'extension | C3: Contrat | D3: Décision d'architecture
A4: Existant confirmé | B4: FGridAttackDefinition | C4: MinDamage, MaxDamage, AccuracyBonus, DamageType, PhysicalSubtype | D4: Actuel uniforme inclusif ; dX multiples exigent une évolution.
A5: Existant confirmé | B5: FGridCombatRollTrace | C5: Kind=Die|Range, DiceCount, DiceSides, IndividualRolls, FinalValue | D5: À enrichir pour le K de la formule et conserver la présentation des jets legacy.
A6: Existant confirmé | B6: FGridOffensiveEquipmentProfile | C6: AttackDefinition, FlatDamageBonus, DamageScalingAttribute, RangeCells | D6: Permet de convertir les valeurs calculées en profils d'attaques.
A7: Existant confirmé | B7: FGridCombatWeaponAttackProfile | C7: WeaponDamagePercent, bUseEquippedWeapon, RequiredItemTags, bUseWeaponRange | D7: Les talents gardent autorité sur WD; pas de duplication.
A8: Existant confirmé | B8: FGridItemInstance | C8: RuntimeObjectId, ItemDefinitionId, Quantity, WorldTransform, équipement | D8: Ne contient pas encore à lui seul la rareté/forge/runes (constat sur en-tête consulté).
A9: Évolution proposée | B9: FGridItemInstance (SaveGame) | C9: ItemLevel (création seulement), Rarity, AffixIds, RuneIds, ForgeRank et enduit | D9: Séparer niveau IMMUTABLE de la finition ; sauvegarder instance
A10: Évolution proposée | B10: Authoring des versions de butin | C10: ArchetypeId + ItemLevel immuable -> profil NdM+K explicite | D10: La courbe k1/k2 sert à l'équilibrage seulement, jamais au tirage runtime.
A11: Évolution proposée | B11: Weapon stat resolver | C11: Lire niveau fixe + rareté + améliorations, calculer le profil sans mutation du niveau | D11: Même projection C++ pour combat, tooltip et examen
A12: À retirer lors de la migration ARMEMENT | B12: Conversion Min/Max en dé virtuel | C12: Interdite pour les nouvelles armes : d5/d7... non autorisés | D12: Conserver exclusivement comme représentation éventuelle des profils legacy étrangers au nouveau catalogue.
